<?xml version="1.0"?>

<!-- URDF DESCRIPTION OF THE DIFFERENTIAL DRIVE ROBOT -->
<!-- Made by Aleksandar Haber -->
<!-- See the license! -->
<!-- This code is the ownership of Aleksandar Haber -->

<!-- FOR ALL THE DIMENSIONS SEE THE PDF FILES THAT COME WITH THIS TUTORIAL -->

<robot name="differential_drive_robot" xmlns:xacro="http://www.ros.org/wiki/xacro">

  <!-- Geometry and constants -->

  <!-- Pi constant -->
  <xacro:property name="pi_const" value="3.14159265"/>

  <!-- Body dimensions -->
  <xacro:property name="a" value="1" />
  <xacro:property name="b" value="0.3" />
  <xacro:property name="c" value="0.6"/>

  <!-- Wheel and caster dimensions -->
  <!-- Wheel and caster radius -->
  <xacro:property name="r" value="0.15"/>
  <!-- Wheel width -->
  <xacro:property name="d" value="0.1"/>

  <!-- Derived dimensions -->
  <xacro:property name="s1" value="${b/2+r}"/>
  <xacro:property name="s2" value="${2*r}"/>
  <xacro:property name="s3" value="${2*r}"/>
  <xacro:property name="s4" value="${c/2+d/2}"/>

  <!-- Body material density -->
  <xacro:property name="d1" value="2710.0"/>
  <!-- Wheel material density -->
  <xacro:property name="d2" value="2710.0"/>
  <!-- Caster material density -->
  <xacro:property name="d3" value="2710.0"/>

  <!-- Robot body mass, wheel mass, caster mass -->
  <!-- body -->
  <xacro:property name="m1" value="${d1*a*b*c}"/>
  <!-- wheel -->
  <xacro:property name="m2" value="${d2*pi_const*r*r*d}"/>
  <!-- caster -->
  <xacro:property name="m3" value="${d3*(4.0/3.0)*pi_const*r*r*r}"/>

  <!-- Moments of inertia of the robot body -->
  <xacro:property name="Ix_body" value="${(1/12)*m1*(b*b+c*c)}"/>
  <xacro:property name="Iy_body" value="${(1/12)*m1*(a*a+b*b)}"/>
  <xacro:property name="Iz_body" value="${(1/12)*m1*(a*a+c*c)}"/>

  <!-- Moments of inertia of the wheels -->
  <xacro:property name="Iz_wheel" value="${0.5*m2*r*r}"/>
  <xacro:property name="I_wheel" value="${(1.0/12.0)*m2*(3.0*r*r+d*d)}"/>

  <!-- Moments of inertia of the caster sphere -->
  <xacro:property name="I_caster" value="${(2.0/5.0)*m3*r*r}"/>

<xacro:macro name="inertia_body">
  <inertial>
    <origin rpy="0 0 0" xyz="0 0 ${s1}"/>
    <mass value="${m1}"/>
    <inertia ixx="${Ix_body}" ixy="0.0" ixz="0.0" iyy="${Iy_body}" iyz="0" izz="${Iz_body}" />
  </inertial>
</xacro:macro>

  <xacro:macro name="inertia_wheel">
  <inertial>
    <origin rpy="1.570795 0 0" xyz="0 0 0"/>
    <mass value="${m2}"/>
    <inertia ixx="${I_wheel}" ixy="0.0" ixz="0.0" iyy="${I_wheel}" iyz="0" izz="${Iz_wheel}" />
  </inertial>
</xacro:macro>

  <xacro:macro name="inertia_caster">
  <inertial>
    <origin rpy="0 0 0" xyz="0 0 0"/>
    <mass value="${m3}"/>
    <inertia ixx="${I_caster}" ixy="0.0" ixz="0.0" iyy="${I_caster}" iyz="0" izz="${I_caster}" />
  </inertial>
  </xacro:macro>

  <xacro:include filename="$(find mobile_robot)/model/robot.gazebo"/>

  <link name="base_footprint"/>

  <joint name="body_link_joint" type="fixed">
    <parent link="base_footprint"/>
    <child link="body_link"/>
  </joint>

  <link name="body_link">
    <visual>
      <geometry>
        <box size="${a} ${c} ${b}"/>
      </geometry>
      <origin rpy="0 0 0" xyz="0 0 ${s1}"/>
    </visual>

    <collision>
      <geometry>
        <box size="${a} ${c} ${b}"/>
      </geometry>
      <origin rpy="0 0 0" xyz="0 0 ${s1}"/>
    </collision>

    <xacro:inertia_body/>
  </link>

  <joint name="wheel1_joint" type="continuous">
    <parent link="body_link"/>
    <child link="wheel1_link"/>
    <origin xyz="${-s2} ${-s4} ${r}" rpy="0 0 0"/>
    <axis xyz="0 1 0"/>
    <limit effort="50000" velocity="10"/>
    <dynamics damping="1.0" friction="1.0"/>
  </joint>

  <link name="wheel1_link">
    <visual>
      <origin rpy="1.570795 0 0" xyz="0 0 0"/>
      <geometry>
        <cylinder length="${d}" radius="${r}"/>
      </geometry>
    </visual>

    <collision>
      <origin rpy="1.570795 0 0" xyz="0 0 0"/>
      <geometry>
        <cylinder length="${d}" radius="${r}"/>
      </geometry>
    </collision>

    <xacro:inertia_wheel/>
  </link>

  <joint name="wheel2_joint" type="continuous">
    <parent link="body_link"/>
    <child link="wheel2_link"/>
    <origin xyz="${-s2} ${s4} ${r}" rpy="0 0 0"/>
    <axis xyz="0 1 0"/>
    <limit effort="50000" velocity="10"/>
    <dynamics damping="1.0" friction="1.0"/>
  </joint>


  <link name="wheel2_link">
    <visual>
      <origin rpy="1.570795 0 0" xyz="0 0 0"/>
      <geometry>
        <cylinder length="${d}" radius="${r}"/>
      </geometry>
    </visual>

    <collision>
      <origin rpy="1.570795 0 0" xyz="0 0 0"/>
      <geometry>
        <cylinder length="${d}" radius="${r}"/>
      </geometry>
    </collision>

    <xacro:inertia_wheel/>
  </link>

</robot>